Workbook

Sheet 00_はじめに・使い方
B1: Version：1.0
B2: HSPの働き方ゼミ
B3: 働き方の取扱説明書
B4: 3STEP・推奨3か月で「自分に合った働き方」を言語化するワークブック
B6: このワークブックは、 「仕事がしんどい。でも、辞めるべきか分からない」 というHSP会社員が、自分に合った働き方を整理するための教材です。 正解を誰かに教えてもらうことが目的ではありません。 自分は何に疲れるのか。 どんな環境なら働きやすいのか。 どこまでなら頑張れるのか。 どんな職場は避けたいのか。 これらを少しずつ言葉にして、最終的に「自分の働き方の取扱説明書」を完成させます。 すべてを一気に進める必要はありません。 1STEPにつき約1か月を目安に、自分のペースで取り組んでください。
B8: このファイルは原本です。 ご自身で記入する場合は、自分用にコピーしてからご利用ください。 定期的に内容を見直し、「働き方の取扱説明書」をアップデートしていきましょう。
B9: コピーの方法（Googleスプレッドシート）：メニューの「ファイル」→「コピーを作成」→ 名前を「働き方の取扱説明書_自分の名前」などに変更して保存。 （Excel）：「名前を付けて保存」で自分用のファイルを作成。
B11: 進め方：3STEP → 完成
B13: STEP1｜自分を知る | C13: ▶ | D13: STEP2｜今を整える | E13: ▶ | F13: STEP3｜これからを選ぶ | G13: ▶ | H13: 完成
B14: なぜ私は仕事で消耗するのか？ | D14: 今の職場でもう少しラクに働けないか？ | F14: 残る・辞める・転職するをどう判断するか？ | H14: 迷ったとき、何度でも戻ってこられる 自分専用の判断ツール
B15: 01_働き方セルフチェック 02_消耗ポイント 03_働きやすい条件 04_頑張りすぎパターン | D15: 05_変えられること・ 変えられないこと 06_仕事の境界線 07_相談ルート | F15: 08_残る・転職する判断基準 09_Must・Want・NG 10_90日行動計画 | H15: 11_私の働き方の 取扱説明書
B16: 目安：1か月目 | D16: 目安：2か月目 | F16: 目安：3か月目 | H16: 3か月ごとに見直し
B18: 目次・進み具合チェック
B19: 終わったシートは「完了」欄を「☑ 完了」にしましょう。どこまで進んだかが一目で分かります。
B20: STEP | C20: シート | E20: このシートで分かること | H20: 完了
B21: STEP1 | C21: 01_働き方セルフチェック | E21: 今の働き方の状態 | H21: ☐ 未完了
B22: STEP1 | C22: 02_消耗ポイント | E22: 私は何に疲れているのか | H22: ☐ 未完了
B23: STEP1 | C23: 03_働きやすい条件 | E23: どんな環境なら働きやすいのか | H23: ☐ 未完了
B24: STEP1 | C24: 04_頑張りすぎパターン | E24: 自分が無理を始めるパターン | H24: ☐ 未完了
B25: STEP2 | C25: 05_変えられること・変えられないこと | E25: 今の職場で改善できること | H25: ☐ 未完了
B26: STEP2 | C26: 06_仕事の境界線 | E26: 頑張る・断る・休む基準と、自分を守るルール | H26: ☐ 未完了
B27: STEP2 | C27: 07_相談ルート | E27: ひとりで抱え込まないための相談先 | H27: ☐ 未完了
B28: STEP3 | C28: 08_残る・転職する判断基準 | E28: 気分ではなく、自分の基準での判断 | H28: ☐ 未完了
B29: STEP3 | C29: 09_Must・Want・NG | E29: 次の職場の条件と「絶対にやりたくないこと」 | H29: ☐ 未完了
B30: STEP3 | C30: 10_90日行動計画 | E30: これから90日でやること | H30: ☐ 未完了
B31: 完成 | C31: 11_私の働き方の取扱説明書 | E31: 1〜2ページで見返せる、自分専用の取扱説明書 | H31: ☐ 未完了
B32: 進み具合 | C32: ="完了 "&COUNTIF(H21:H31,"☑ 完了")&" / 11 シート"
B34: 記入のルール
B35: 黄色のセル | C35: あなたの記入欄です。ここに書き込みます。
B36: グレーのセル | C36: 記入例です。書き方の参考にしてください（消さずに残してOK）。
B37: 薄いグレー（数字） | C37: 自動で計算される欄です（入力不要）。
B38: ▼ ドロップダウン | C38: セルを選ぶと選択肢が表示されます。「自由入力も可」の欄は直接書き込んでもOK。
B39: ☐ 未完了／☑ 完了 | C39: 完了欄は選択式のチェックです。
B40: ★ まとめ欄 | C40: 各シートの★まとめ欄は「11_私の働き方の取扱説明書」に自動で反映されます。
B42: おすすめの使い方
B43: ・1STEPにつき約1か月が目安です。1回15〜30分、週1回ほど開くペースで十分です。 ・うまく書けなくても大丈夫。単語やメモ書きからで構いません。あとから何度でも書き直せます。 ・しんどいときは無理に進めず、休むことを優先してください。 ・完成後は3か月に1回、または「辞めたい」「迷う」と感じたときに「11_私の働き方の取扱説明書」を見返し、アップデートしましょう。 ・ゼミのワークや個別相談のときに、このファイルを手元に置いておくと話がスムーズです。 ・Googleスプレッドシートでチェックボックスを使いたい場合は、完了欄を選んで「挿入」→「チェックボックス」に置き換えることもできます（その場合、進み具合の自動集計は使えなくなります）。
B45: ご注意
B46: この教材は、HSPの診断・医療診断・心理療法・メンタル不調の治療を目的としたものではありません。 セルフチェックの点数は、今の働き方をふり返るための目安であり、何かを判定するものではありません。 強い心身の不調や生活に支障がある場合は、無理をせず医療・心理等の専門家へご相談ください。
B48: バージョン情報・更新履歴
B49: Version | C49: 更新日 | E49: 更新内容
...

Sheet 01_働き方セルフチェック
A1: STEP1｜自分を知る 01 働き方セルフチェック
A2: 目的：今の働き方の状態を確認する（なぜ私は仕事で消耗するのか？の入口）
A3: ① 各質問に、今の自分に近いものをドロップダウンで選びます（深く考えすぎず、直感でOK）。 ② 3か月後（STEP3が終わる頃）にもう一度回答して、変化を比べてみましょう。 ③ 最後に「気づいたこと」を一言メモします。点数は良い・悪いを決めるものではありません。
A4: ■ 黄色＝あなたの記入欄 | C4: ■ グレー＝記入例 | D4: 所要時間の目安：約10分 ／ 記入例は消さずに残してOK。行が足りなければ、記入欄の行をコピーして増やせます。
A6: No. | B6: 質問 | C6: カテゴリ | D6: 開始時の回答 | E6: 点 | F6: 3か月後の回答 | G6: 点 | H6: メモ（具体的な場面など） | J6: 回答の選択肢 | K6: 点
A7: 例 | B7: （例）休日になっても疲れが抜けない | C7: 記入例 | D7: とても当てはまる | E7: 5 | F7: 少し当てはまる | G7: 4 | H7: 日曜の夕方になると月曜のことを考えてしまう | J7: まったく当てはまらない | K7: 1
A8: 1 | B8: 仕事が終わっても頭から仕事が離れない | C8: 心と体の疲れ | E8: =IF(D8="","",MATCH(D8,$J$7:$J$11,0)) | G8: =IF(F8="","",MATCH(F8,$J$7:$J$11,0)) | J8: あまり当てはまらない | K8: 2
A9: 2 | B9: 休日になっても疲れが抜けない | C9: 心と体の疲れ | E9: =IF(D9="","",MATCH(D9,$J$7:$J$11,0)) | G9: =IF(F9="","",MATCH(F9,$J$7:$J$11,0)) | J9: どちらともいえない | K9: 3
A10: 3 | B10: 頼まれた仕事を断るのが苦手 | C10: 頑張りすぎ・境界線 | E10: =IF(D10="","",MATCH(D10,$J$7:$J$11,0)) | G10: =IF(F10="","",MATCH(F10,$J$7:$J$11,0)) | J10: 少し当てはまる | K10: 4
A11: 4 | B11: 周囲の機嫌や評価が気になる | C11: 頑張りすぎ・境界線 | E11: =IF(D11="","",MATCH(D11,$J$7:$J$11,0)) | G11: =IF(F11="","",MATCH(F11,$J$7:$J$11,0)) | J11: とても当てはまる | K11: 5
A12: 5 | B12: 仕事を抱え込みやすい | C12: 頑張りすぎ・境界線 | E12: =IF(D12="","",MATCH(D12,$J$7:$J$11,0)) | G12: =IF(F12="","",MATCH(F12,$J$7:$J$11,0))
A13: 6 | B13: 周囲が忙しいと自分だけ帰りにくい | C13: 頑張りすぎ・境界線 | E13: =IF(D13="","",MATCH(D13,$J$7:$J$11,0)) | G13: =IF(F13="","",MATCH(F13,$J$7:$J$11,0))
A14: 7 | B14: 急な予定変更が続くと疲れる | C14: 環境との相性 | E14: =IF(D14="","",MATCH(D14,$J$7:$J$11,0)) | G14: =IF(F14="","",MATCH(F14,$J$7:$J$11,0))
A15: 8 | B15: マルチタスクが続くと消耗する | C15: 環境との相性 | E15: =IF(D15="","",MATCH(D15,$J$7:$J$11,0)) | G15: =IF(F15="","",MATCH(F15,$J$7:$J$11,0))
A16: 9 | B16: 静かな環境の方が集中しやすい | C16: 環境との相性 | E16: =IF(D16="","",MATCH(D16,$J$7:$J$11,0)) | G16: =IF(F16="","",MATCH(F16,$J$7:$J$11,0))
A17: 10 | B17: 頑張りすぎてから「無理していた」と気づく | C17: 心と体の疲れ | E17: =IF(D17="","",MATCH(D17,$J$7:$J$11,0)) | G17: =IF(F17="","",MATCH(F17,$J$7:$J$11,0))
A18: 11 | B18: 今の働き方をこの先も続けられるか不安 | C18: これからへの迷い | E18: =IF(D18="","",MATCH(D18,$J$7:$J$11,0)) | G18: =IF(F18="","",MATCH(F18,$J$7:$J$11,0))
A19: 12 | B19: 転職したいと思うことがある | C19: これからへの迷い | E19: =IF(D19="","",MATCH(D19,$J$7:$J$11,0)) | G19: =IF(F19="","",MATCH(F19,$J$7:$J$11,0))
A20: 13 | B20: 自分に合う職場の条件が分からない | C20: これからへの迷い | E20: =IF(D20="","",MATCH(D20,$J$7:$J$11,0)) | G20: =IF(F20="","",MATCH(F20,$J$7:$J$11,0))
A21: 14 | B21: 休むタイミングが分からない | C21: 心と体の疲れ | E21: =IF(D21="","",MATCH(D21,$J$7:$J$11,0)) | G21: =IF(F21="","",MATCH(F21,$J$7:$J$11,0))
A22: 15 | B22: 「もっと頑張らないと」と思いがち | C22: 頑張りすぎ・境界線 | E22: =IF(D22="","",MATCH(D22,$J$7:$J$11,0)) | G22: =IF(F22="","",MATCH(F22,$J$7:$J$11,0))
A23: 合計点（参考・15〜75点） | D23: 開始時 | E23: =SUM(E8:E22) | F23: 3か月後 | G23: =SUM(G8:G22)
A24: 回答した質問の数 | D24: 開始時 | E24: =COUNT(E8:E22) | F24: 3か月後 | G24: =COUNT(G8:G22)
A26: カテゴリ別のふり返り（平均点が高いところ＝今、負担がかかりやすいところのヒント）
A27: カテゴリ | C27: 質問数 | D27: 開始時の平均 | F27: 3か月後の平均 | H27: 次に深掘りするシート
A28: 心と体の疲れ | C28: =COUNTIF($C$8:$C$22,A28) | D28: =IFERROR(ROUND(AVERAGEIF($C$8:$C$22,A28,$E$8:$E$22),1),"-") | F28: =IFERROR(ROUND(AVERAGEIF($C$8:$C$22,A28,$G$8:$G$22),1),"-") | H28: 02_消耗ポイント／06_仕事の境界線
A29: 頑張りすぎ・境界線 | C29: =COUNTIF($C$8:$C$22,A29) | D29: =IFERROR(ROUND(AVERAGEIF($C$8:$C$22,A29,$E$8:$E$22),1),"-") | F29: =IFERROR(ROUND(AVERAGEIF($C$8:$C$22,A29,$G$8:$G$22),1),"-") | H29: 04_頑張りすぎパターン／06／07
A30: 環境との相性 | C30: =COUNTIF($C$8:$C$22,A30) | D30: =IFERROR(ROUND(AVERAGEIF($C$8:$C$22,A30,$E$8:$E$22),1),"-") | F30: =IFERROR(ROUND(AVERAGEIF($C$8:$C$22,A30,$G$8:$G$22),1),"-") | H30: 02／03_働きやすい条件／09
A31: これからへの迷い | C31: =COUNTIF($C$8:$C$22,A31) | D31: =IFERROR(ROUND(AVERAGEIF($C$8:$C$22,A31,$E$8:$E$22),1),"-") | F31: =IFERROR(ROUND(AVERAGEIF($C$8:$C$22,A31,$G$8:$G$22),1),"-") | H31: 08_残る・転職する判断基準／09／10
A33: 点数の読み方：点数は「今の働き方の状態」をふり返るための目安です。HSPかどうかや、心身の状態を判定する診断ではありません。点数が高くても低くても、良い・悪いはありません。平均が高かったカテゴリから、関連するシートを優先して取り組んでみましょう。
A34: ※ この教材は、HSPの診断・医療診断・心理療法・メンタル不調の治療を目的としたものではありません。強い心身の不調や生活に支障がある場合は、無理をせず医療・心理等の専門家へご相談ください。
A36: セルフチェックで気づいたこと
A37: 例 | B37: （例）「頑張りすぎ・境界線」の点が一番高かった。疲れの原因は仕事量より、断れないことにあるのかもしれない。
A38: 記入

Sheet 02_消耗ポイント
A1: STEP1｜自分を知る 02 消耗ポイント
A2: 目的：私は何に疲れているのか？を明確にする
A3: ① ここ1〜2週間で「疲れたな」と感じた場面を、思い出せる範囲で書き出します（1日1行でもOK）。 ② 「特に疲れた要素」をドロップダウンから選び、疲労度を1〜5で記入します。 ③ 下の集計を参考に、「私が消耗しやすい条件 TOP5」を自分の言葉でまとめます。
A4: ■ 黄色＝あなたの記入欄 | C4: ■ グレー＝記入例 | D4: 所要時間の目安：約20分（＋2週間ほど記録を続けるのがおすすめ） ／ 記入例は消さずに残してOK。行が足りなければ、記入欄の行をコピーして増やせます。
A6: No. | B6: 日付 | C6: 最近疲れた場面 | D6: 何が起きた？ | E6: 特に疲れた要素 | F6: 疲労度 1〜5 | G6: 次回どうしたい？
A7: 例 | B7: 10/6 | C7: 月曜午前、朝礼のあと | D7: 上司から急ぎの資料依頼が3件重なり、その間も電話が鳴り続けた | E7: マルチタスク | F7: 5 | G7: 依頼が重なったら、その場で上司に優先順位を確認する
A8: 例 | B8: 10/9 | C8: 部署の飲み会 | D8: 2時間、周りに気を遣って話を合わせ続けた。帰宅後もぐったり | E8: 人間関係 | F8: 4 | G8: 一次会で帰る。参加は月1回までにする
A9: 1
A10: 2
A11: 3
A12: 4
A13: 5
A14: 6
A15: 7
A16: 8
A17: 9
A18: 10
A19: 11
A20: 12
A22: 疲れた要素の集計（TOP5を考えるヒント）
A23: 回数が多い要素・疲労度が高い要素が、あなたの「消耗ポイント」の候補です。数字はあくまで参考に。
A24: 疲れた要素 | D24: 記録した回数 | E24: 疲労度の平均
A25: 仕事内容 | D25: =COUNTIF($E$9:$E$20,A25) | E25: =IFERROR(ROUND(AVERAGEIF($E$9:$E$20,A25,$F$9:$F$20),1),"-")
A26: 仕事量 | D26: =COUNTIF($E$9:$E$20,A26) | E26: =IFERROR(ROUND(AVERAGEIF($E$9:$E$20,A26,$F$9:$F$20),1),"-")
A27: 人間関係 | D27: =COUNTIF($E$9:$E$20,A27) | E27: =IFERROR(ROUND(AVERAGEIF($E$9:$E$20,A27,$F$9:$F$20),1),"-")
A28: 音・環境 | D28: =COUNTIF($E$9:$E$20,A28) | E28: =IFERROR(ROUND(AVERAGEIF($E$9:$E$20,A28,$F$9:$F$20),1),"-")
A29: 電話 | D29: =COUNTIF($E$9:$E$20,A29) | E29: =IFERROR(ROUND(AVERAGEIF($E$9:$E$20,A29,$F$9:$F$20),1),"-")
A30: 突発対応 | D30: =COUNTIF($E$9:$E$20,A30) | E30: =IFERROR(ROUND(AVERAGEIF($E$9:$E$20,A30,$F$9:$F$20),1),"-")
A31: マルチタスク | D31: =COUNTIF($E$9:$E$20,A31) | E31: =IFERROR(ROUND(AVERAGEIF($E$9:$E$20,A31,$F$9:$F$20),1),"-")
A32: 責任 | D32: =COUNTIF($E$9:$E$20,A32) | E32: =IFERROR(ROUND(AVERAGEIF($E$9:$E$20,A32,$F$9:$F$20),1),"-")
A33: 評価 | D33: =COUNTIF($E$9:$E$20,A33) | E33: =IFERROR(ROUND(AVERAGEIF($E$9:$E$20,A33,$F$9:$F$20),1),"-")
A34: 残業 | D34: =COUNTIF($E$9:$E$20,A34) | E34: =IFERROR(ROUND(AVERAGEIF($E$9:$E$20,A34,$F$9:$F$20),1),"-")
A35: 通勤 | D35: =COUNTIF($E$9:$E$20,A35) | E35: =IFERROR(ROUND(AVERAGEIF($E$9:$E$20,A35,$F$9:$F$20),1),"-")
A36: その他 | D36: =COUNTIF($E$9:$E$20,A36) | E36: =IFERROR(ROUND(AVERAGEIF($E$9:$E$20,A36,$F$9:$F$20),1),"-")
A38: ★ 私が消耗しやすい条件 TOP5
A39: 「どんな条件のとき、私は消耗するのか」を一文で書きます。→ 11_私の働き方の取扱説明書に自動で反映されます。
A40: 順位 | B40: 私が消耗しやすい条件 | E40: 具体的にはどんなとき？
A41: 例 | B41: 急ぎの依頼が重なり、マルチタスクになるとき | E41: 朝イチの依頼と電話対応が重なる月曜の午前中
A42: 1
A43: 2
...

Sheet 03_働きやすい条件
A1: STEP1｜自分を知る 03 働きやすい条件
A2: 目的：私はどんな環境なら働きやすいのか？を明確にする
A3: ① 「この日は気持ちよく働けた」「この仕事はやりやすかった」場面を書き出します（今の職場・過去の職場・アルバイトなど何でもOK）。 ② 何が良かったのかを考え、「条件」をドロップダウンから選び（自由入力も可）、自分にとっての重要度を1〜5で記入します。 ③ 下の集計を参考に、「私が働きやすい条件 TOP5」をまとめます。
A4: ■ 黄色＝あなたの記入欄 | C4: ■ グレー＝記入例 | D4: 所要時間の目安：約20分 ／ 記入例は消さずに残してOK。行が足りなければ、記入欄の行をコピーして増やせます。
A6: No. | B6: 働きやすかった場面 | C6: 何が良かった？ | D6: 条件 | E6: 重要度 1〜5 | F6: 今の職場で増やせそう？（メモ）
A7: 例 | B7: 在宅勤務の日に企画書を作った | C7: 誰にも話しかけられず、2時間集中できた。疲れ方が全然違った | D7: リモートワーク | E7: 5 | F7: 週1回の在宅を週2回にできないか上司に聞いてみる
A8: 例 | B8: 新人研修の資料づくり | C8: 目的と期限がはっきり伝えられ、進め方は任せてもらえた | D8: 裁量がある | E8: 4 | F8: 依頼を受けるときに、目的と期限を必ず確認する
A9: 1
A10: 2
A11: 3
A12: 4
A13: 5
A14: 6
A15: 7
A16: 8
A17: 9
A18: 10
A19: 11
A20: 12
A22: 働きやすい条件の集計（TOP5を考えるヒント）
A23: 何度も出てくる条件・重要度が高い条件が、あなたの「働きやすさの土台」の候補です。
A24: 条件 | C24: 記録した回数 | D24: 重要度の平均
A25: 静かな環境 | C25: =COUNTIF($D$9:$D$20,A25) | D25: =IFERROR(ROUND(AVERAGEIF($D$9:$D$20,A25,$E$9:$E$20),1),"-")
A26: 一人で集中する時間 | C26: =COUNTIF($D$9:$D$20,A26) | D26: =IFERROR(ROUND(AVERAGEIF($D$9:$D$20,A26,$E$9:$E$20),1),"-")
A27: 明確な指示 | C27: =COUNTIF($D$9:$D$20,A27) | D27: =IFERROR(ROUND(AVERAGEIF($D$9:$D$20,A27,$E$9:$E$20),1),"-")
A28: 裁量がある | C28: =COUNTIF($D$9:$D$20,A28) | D28: =IFERROR(ROUND(AVERAGEIF($D$9:$D$20,A28,$E$9:$E$20),1),"-")
A29: 残業が少ない | C29: =COUNTIF($D$9:$D$20,A29) | D29: =IFERROR(ROUND(AVERAGEIF($D$9:$D$20,A29,$E$9:$E$20),1),"-")
A30: 人間関係が穏やか | C30: =COUNTIF($D$9:$D$20,A30) | D30: =IFERROR(ROUND(AVERAGEIF($D$9:$D$20,A30,$E$9:$E$20),1),"-")
A31: 電話が少ない | C31: =COUNTIF($D$9:$D$20,A31) | D31: =IFERROR(ROUND(AVERAGEIF($D$9:$D$20,A31,$E$9:$E$20),1),"-")
A32: リモートワーク | C32: =COUNTIF($D$9:$D$20,A32) | D32: =IFERROR(ROUND(AVERAGEIF($D$9:$D$20,A32,$E$9:$E$20),1),"-")
A33: 通勤時間が短い | C33: =COUNTIF($D$9:$D$20,A33) | D33: =IFERROR(ROUND(AVERAGEIF($D$9:$D$20,A33,$E$9:$E$20),1),"-")
A34: 突発対応が少ない | C34: =COUNTIF($D$9:$D$20,A34) | D34: =IFERROR(ROUND(AVERAGEIF($D$9:$D$20,A34,$E$9:$E$20),1),"-")
A35: 仕事量が一定 | C35: =COUNTIF($D$9:$D$20,A35) | D35: =IFERROR(ROUND(AVERAGEIF($D$9:$D$20,A35,$E$9:$E$20),1),"-")
A36: 評価基準が明確 | C36: =COUNTIF($D$9:$D$20,A36) | D36: =IFERROR(ROUND(AVERAGEIF($D$9:$D$20,A36,$E$9:$E$20),1),"-")
A37: その他 | C37: =COUNTIF($D$9:$D$20,A37) | D37: =IFERROR(ROUND(AVERAGEIF($D$9:$D$20,A37,$E$9:$E$20),1),"-")
A39: ★ 私が働きやすい条件 TOP5
A40: 「この条件があると、私は力を発揮しやすい」を一文で書きます。→ 11_私の働き方の取扱説明書に自動で反映されます。
A41: 順位 | B41: 私が働きやすい条件 | D41: なぜ大事？（具体例）
A42: 例 | B42: 一人で集中できる時間が、1日のうちに2時間以上ある | D42: 中断されないと、同じ仕事でも疲れ方が半分くらいになる
A43: 1
...

Sheet 04_頑張りすぎパターン
A1: STEP1｜自分を知る 04 頑張りすぎパターン
A2: 目的：自分が無理を始めるパターンを知る
A3: ① 「あとから思えば無理していた」場面を思い出し、そのとき頭の中で考えていたこと・とった行動・結果を書きます。 ② 責める必要はありません。「こういうとき、私はこう動きやすい」と観察するつもりで書くのがコツです。 ③ 似たパターンをまとめて、「私が頑張りすぎ始める3つのパターン」に整理します。
A4: ■ 黄色＝あなたの記入欄 | C4: ■ グレー＝記入例 | D4: 所要時間の目安：約20分 ／ 記入例は消さずに残してOK。行が足りなければ、記入欄の行をコピーして増やせます。
A6: よくある頑張りすぎパターン（ヒント）
A7: ・頼まれると断れない ・周囲が残業していると帰れない ・期待されると無理して応えようとする ・ミスが怖くて必要以上に確認する ・評価が下がることを恐れて仕事を抱え込む
A9: No. | B9: 状況 | C9: そのとき考えていること | D9: とってしまう行動 | E9: その結果 | F9: 次からどうする？
A10: 例 | B10: 定時直前に、上司から「明日までにお願い」と依頼された | C10: 「断ったら評価が下がる」「自分がやった方が早い」 | D10: その場で「大丈夫です」と引き受け、21時まで残業 | E10: 翌日も疲れが抜けず、集中力が落ちてミスをした | F10: その場で返事をせず「今の業務と、どちらを優先しますか？」と聞く
A11: 例 | B11: 周りがまだ忙しそうにしている18時 | C11: 「先に帰ったら、やる気がないと思われる」 | D11: 急ぎではない作業を探して残る | E11: 家に帰っても気持ちが休まらない | F11: 帰る日は朝のうちに「今日は18時に上がります」と伝えておく
A12: 1
A13: 2
A14: 3
A15: 4
A16: 5
A17: 6
A18: 7
A19: 8
A21: ★ 私が頑張りすぎ始める3つのパターン
A22: 「○○なとき、△△してしまう」の形で書くと分かりやすくなります。→ 11_私の働き方の取扱説明書に自動で反映されます。
A23: No. | B23: パターン（○○なとき、△△してしまう） | D23: 気づくためのサイン | F23: 対処法・合言葉
A24: 例 | B24: 期待されると、キャパを超えても引き受けてしまう | D24: 「大丈夫です」と即答している自分に気づいたとき | F24: 「確認して折り返します」
A25: 1
A26: 2
A27: 3

Sheet 05_変えられること・変えられないこと
A1: STEP2｜今を整える 05 変えられること・変えられないこと
A2: 目的：今の職場で改善できることを整理する（今の職場でもう少しラクに働けないか？）
A3: ① STEP1で見えた消耗ポイントや悩みを「悩み・問題」に書きます。 ② それぞれについて「自分で変えられる部分」「相談すれば変わる可能性がある部分」「自分では変えにくい部分」に分けて書きます。1つの悩みを3つに分解するイメージです。 ③ 最後に「今月まず変えてみること」を1〜3個だけ選びます。全部を一度に変えようとしなくて大丈夫です。
A4: ■ 黄色＝あなたの記入欄 | C4: ■ グレー＝記入例 | D4: 所要時間の目安：約20分 ／ 記入例は消さずに残してOK。行が足りなければ、記入欄の行をコピーして増やせます。
A6: 考えるテーマの例：仕事の進め方／仕事量／上司との関係／部署／通勤／会社文化／給与制度／残業／座席／電話対応／業務内容
A8: No. | B8: 悩み・問題 | C8: 自分で変えられる | D8: 相談すれば 変わる可能性あり | E8: 自分では変えにくい | F8: 次のアクション
A9: 例 | B9: 仕事量が多い | C9: 毎朝タスクを書き出し、優先順位をつけてから着手する | D9: 業務量の偏りを上司に相談する | E9: 繁忙期の業務量そのもの | F9: 来週の1on1で業務一覧を見せて相談
A10: 例 | B10: 電話対応で集中が途切れる | C10: 電話のあとに5分だけメモの時間をとる | D10: 電話当番を輪番制にできないか提案する | E10: 部署として電話窓口であること | F10: チームミーティングで当番制を提案
A11: 1
A12: 2
A13: 3
A14: 4
A15: 5
A16: 6
A17: 7
A18: 8
A20: ★ 今月まず変えてみること（1〜3個）
A21: 「自分で変えられる」「相談すれば変わる可能性あり」の中から、小さく始められるものを選びましょう。
A22: No. | B22: 変えてみること | D22: いつ・どうやって？ | E22: やってみてどうだった？（月末にふり返り）
A23: 例 | B23: 朝いちばんに、その日のタスクを3つに絞る | D23: 毎朝始業後の5分 | E23: 午前中の焦りが減った。急ぎの依頼が来ても、何を後回しにするか決めやすくなった
A24: 1
A25: 2
A26: 3

Sheet 06_仕事の境界線
A1: STEP2｜今を整える 06 仕事の境界線
A2: 目的：自分を守るためのルールを決める
A3: ① 「頑張る基準」「断る・相談する基準」「休む基準」の3つについて、問いに答える形で自分の基準を書きます。 ② 基準は「〜したら」「〜のときは」のように、あとで自分が判断できる具体的な形にするのがコツです。 ③ 最後に「私を守る5つの働き方ルール」にまとめます。
A4: ■ 黄色＝あなたの記入欄 | C4: ■ グレー＝記入例 | D4: 所要時間の目安：約25分 ／ 記入例は消さずに残してOK。行が足りなければ、記入欄の行をコピーして増やせます。
A6: 項目 | B6: 考えるヒント（問い） | C6: 私の基準 | D6: 具体例・伝え方
A7: 頑張る基準 どんな状態なら 頑張っても大丈夫か | B7: （記入例） | C7: 睡眠が6時間以上とれていて、週末に回復できている状態なら頑張ってOK | D7: 繁忙期の2週間だけは残業OK。3週目に入ったら上司に相談する
B8: どんな状態なら、頑張っても大丈夫？
B9: 頑張るのは、どのくらいの期間・量まで？
B10: 頑張ったあと、どうやって回復する？
A11: 断る・相談する 基準 どんな仕事は 断る・相談するか | B11: （記入例） | C11: 今週の締切を超える新規依頼は、その場で受けずに優先順位を確認する | D11: 「今○○を進めていて、△日以降なら対応できます。どちらを優先しますか？」
B12: どんな仕事は、断る・相談する？
B13: どのくらいの量・状態になったら相談する？
B14: 断るとき・相談するとき、どう伝える？
A15: 休む基準 どんなサインが出たら 一度立ち止まるか | B15: （記入例） | C15: 日曜の夜に眠れない日が2週続いたら、立ち止まる | D15: 有休を1日とる／信頼できる人に話す／相談ルート（07）を使う
B16: 体のどんなサインが出たら立ち止まる？
B17: 心や行動のどんなサインが出たら立ち止まる？
B18: 立ち止まったら、まず何をする？
A19: ※ 休む基準は「限界まで我慢しないための目安」です。強い心身の不調や生活に支障がある場合は、基準に関わらず、無理をせず医療・心理等の専門家へご相談ください。
A21: ★ 私を守る5つの働き方ルール
A22: 上の基準から、毎日の働き方で守りたいルールを5つに絞ります。「〜する」「〜しない」の形で短く。→ 11_私の働き方の取扱説明書に自動で反映されます。
A23: 例 | B23: 18時以降に来た依頼は、翌朝に優先順位を確認してから着手する
A24: ルール 1
A25: ルール 2
A26: ルール 3
A27: ルール 4
A28: ルール 5

Sheet 07_相談ルート
A1: STEP2｜今を整える 07 相談ルート
A2: 目的：ひとりで抱え込まない仕組みを作る
A3: ① 「困ったこと」が起きたとき、誰に・いつ・何を伝えるかを書きます。 ② 「相談するタイミング」は、限界になる前の早めの合図にしておくのがポイントです。 ③ 最後に「私の相談ルート」を分野ごとに簡潔にまとめます。
A4: ■ 黄色＝あなたの記入欄 | C4: ■ グレー＝記入例 | D4: 所要時間の目安：約15分 ／ 記入例は消さずに残してOK。行が足りなければ、記入欄の行をコピーして増やせます。
A6: No. | B6: 困ったこと | C6: 相談する相手 | D6: 相談するタイミング | E6: 伝える内容
A7: 例 | B7: 仕事量が多く、残業が続いている | C7: 上司 | D7: 残業が週10時間を超えた時点で | E7: 抱えている業務の一覧と、どれを優先・後回しにするか一緒に決めてほしいこと
A8: 例 | B8: 眠れない日が続き、仕事に集中できない | C8: 医療・心理・キャリアなどの専門家 | D8: 2週間以上続いたら（我慢しすぎる前に） | E8: いつから・どんな症状か、仕事や生活でどんなことに困っているか
A9: 1
A10: 2
A11: 3
A12: 4
A13: 5
A14: 6
A15: 7
A16: 8
A18: ★ 私の相談ルート
A19: 分野ごとに「最初に相談する相手」と「次の相談先」を決めておきます。→ 11_私の働き方の取扱説明書に自動で反映されます。
A20: 分野 | C20: 最初に相談する相手 | D20: 次の相談先・メモ
A21: （例）仕事量・業務のこと | C21: 直属の上司 | D21: 難しければ、先輩の○○さん → 人事
A22: 仕事量・業務のこと
A23: 職場の人間関係
A24: 心と体の不調
A25: キャリア・転職のこと
A27: ※ 強い心身の不調（眠れない・食べられない・涙が止まらない・朝起き上がれない など）が続く場合は、職場への相談とあわせて、必要に応じて医療等の専門家へ相談してください。強い心身の不調や生活に支障がある場合は、無理をせず医療・心理等の専門家へご相談ください。

Sheet 08_残る・転職する判断基準
A1: STEP3｜これからを選ぶ 08 残る・転職する判断基準
A2: 目的：「辞めたい気分」だけで判断せず、自分の基準で考える
A3: ① 判断項目ごとに、3つの選択肢（残る／異動・調整する／転職を検討する）だと、どうなりそうかを書きます。分からない欄は「？」でOK。 ② STEP1・2で書いた消耗ポイントや働きやすい条件を見ながら書くと、判断がブレにくくなります。 ③ 最後に「今の会社に残れる条件」「環境を変えるサイン」「現時点での判断」をまとめます。結論は「まだ決めない」でも大丈夫です。
A4: ■ 黄色＝あなたの記入欄 | C4: ■ グレー＝記入例 | D4: 所要時間の目安：約30分 ／ 記入例は消さずに残してOK。行が足りなければ、記入欄の行をコピーして増やせます。
A6: 判断項目 | B6: 今の会社に残る | C6: 異動・調整する | D6: 転職を検討する | E6: メモ・気づき
A7: （例）仕事量 | B7: 繁忙期は月40時間の残業。改善の見込みは薄い | C7: 隣の部署は残業月10時間程度らしい | D7: 求人を見ると、月20時間以下の会社も多い | E7: まずは異動の可能性を人事に確認
A8: 消耗ポイント
A9: 働きやすい条件
A10: 仕事量
A11: 人間関係
A12: 給与
A13: 将来性
A14: 心身への負担
A15: 改善可能性
A16: やりたい仕事
A17: 家庭との両立
A20: 納得度（1〜5） | E20: ←各選択肢に、今の気持ちで1〜5をつけてみる
A22: 判断のヒント：「辞めたい」という気持ちが、強く疲れた日だけのものか、2週間以上続いているものかを見てみましょう。疲れが強いときは、大きな決断の前にまず休む・相談する（06・07）ことも選択肢です。「今すぐ決めない」と決めることも、立派な判断です。
A24: ★ 今の会社に残れる条件
A25: 「これが満たされているなら、今の会社で続けられる」という条件。→ 11に自動で反映されます。
A26: 例 | B26: 残業が月20時間以内に収まり、在宅勤務を週2回続けられること
A27: 1
A28: 2
A29: 3
A31: ★ 環境を変える・転職を考えるサイン
A32: 「これが起きたら、環境を変えることを本気で考える」というサイン。→ 11に自動で反映されます。
A33: 例 | B33: 業務量の相談を2回しても、3か月たって何も変わらないとき
A34: 1
A35: 2
A36: 3
A38: ★ 現時点での私の判断
A39: 私の判断 | D39: 判断した日
A40: その理由
A41: 次に見直す日 | C41: 目安：3か月後。気持ちが大きく揺れたときも見直しましょう。

Sheet 09_Must・Want・NG
A1: STEP3｜これからを選ぶ 09 Must・Want・NG
A2: 目的：次の職場を選ぶとき、「やりたいこと」だけでなく「絶対にやりたくないこと」を明確にする
A3: ① 各項目について、Must（絶対に必要）・Want（できれば欲しい）・NG（絶対に避けたい）の基準を書きます。全部埋めなくてOK。こだわりがない項目は空欄で構いません。 ② 迷ったら、02_消耗ポイント（→NGのヒント）と03_働きやすい条件（→Must・Wantのヒント）を見返しましょう。 ③ 最後に、いちばん大切な「絶対にやりたくないことリスト」をつくります。
A4: ■ 黄色＝あなたの記入欄 | C4: ■ グレー＝記入例 | D4: 所要時間の目安：約30分 ／ 記入例は消さずに残してOK。行が足りなければ、記入欄の行をコピーして増やせます。
A6: 検討項目 | B6: Must 絶対に必要な条件 | C6: Want できれば欲しい条件 | D6: NG 絶対に避けたい条件 | E6: 理由（なぜそう思う？）
A7: （例）残業時間 | B7: 月20時間以内 | C7: ほぼ定時で帰れる | D7: 月45時間超えが当たり前 | E7: 前職で残業が続いた時期、休日も回復できなかったから
A8: （例）電話対応 | C8: 電話はほとんどない | D8: 1日中電話を受ける窓口業務 | E8: 電話のたびに集中が切れて、消耗が大きいから
A9: 残業時間
A10: 通勤時間
A11: 年収
A12: リモートワーク
A13: 電話対応
A14: 出張
A15: 転勤
A16: 人間関係
A17: 職場の静かさ
A18: マルチタスク
A19: 個人作業／チーム作業
A20: 裁量
... A30: 上の表のMustから、特に大事なものを最大5つ。→ 11に自動で反映されます。
A31: 例 | B31: 残業は月20時間以内。在宅勤務が週2日以上できる
A32: Must 1
A33: Must 2
A34: Must 3
A35: Must 4
A36: Must 5
A38: ★ 次の職場の NG条件（避けたい条件）まとめ
A39: 上の表のNGから、特に大事なものを最大5つ。→ 11に自動で反映されます。
A40: 例 | B40: 全国転勤がある。1日中電話を受ける業務が中心
A41: NG 1
A42: NG 2
A43: NG 3
A44: NG 4
A45: NG 5
A48: 絶対にやりたくないことリスト
A49: 「やりたいこと」が分からなくても、「やりたくないこと」は意外とはっきりしているものです。 私自身も転職前に「絶対にやりたくないことリスト」をつくり、それを軸に転職先を選びました。求人票の魅力的な言葉に流されず、「ここだけは譲れない」という線を引けたことで、入社後のミスマッチを防げました。 これまでのワークをふり返りながら、5〜10個、遠慮せずに書き出してみてください。
A50: 書き方のヒント（例）：毎日の電話窓口業務／怒鳴る・威圧的な上司がいる職場／終電近くまでの残業が当たり前／全国転勤／個人ノルマで競わせる営業／常に複数の案件を同時進行する役割
A51: No. | B51: 絶対にやりたくないこと | D51: なぜ避けたい？ | E51: 求人・面接でどう確認する？
A52: 例 | B52: 1日中、電話を受ける窓口業務 | D52: 電話のたびに集中が切れて、夕方には何も考えられなくなるから | E52: 面接で「1日の電話件数」「電話当番の有無」を質問する
A53: 1
...

Sheet 10_90日行動計画
A1: STEP3｜これからを選ぶ 10 90日行動計画
A2: 目的：分かっただけで終わらず、行動につなげる
A3: ① これまでのワークをもとに、「やめること」「始めること」「相談すること」「調べること」を1〜3個ずつ書きます。 ② その中から実際に動くものを「実行管理表」に移し、期限と「最初の一歩」（5分でできる行動）を決めます。 ③ 30日・60日・90日の節目にふり返り、完了したら完了欄を「☑ 完了」にします。
A4: ■ 黄色＝あなたの記入欄 | C4: ■ グレー＝記入例 | D4: 所要時間の目安：約20分＋90日間の実行 ／ 記入例は消さずに残してOK。行が足りなければ、記入欄の行をコピーして増やせます。
A6: 4つの行動を決める
A7: 区分 | B7: 内容 | C7: なぜやる？（どのシートの気づきから？）
A8: 例（やめる） | B8: 寝る前に仕事のメールを確認する | C8: 頭から仕事が離れず、眠りが浅くなるから（02・06より）
A9: やめること
A12: 始めること
A15: 相談すること
A18: 調べること
A22: 実行管理表
A23: 完了欄はドロップダウンで「☐ 未完了／☑ 完了」を選べます。
A24: 区分 | B24: 行動 | C24: 期限 | E24: 最初の一歩（5分でできること） | F24: 完了
A25: 例（相談） | B25: 上司に業務量を相談する | C25: 11/15 | E25: 1on1の議題メモに「業務量」と書いておく | F25: ☑ 完了
F26: ☐ 未完了
F27: ☐ 未完了
F28: ☐ 未完了
F29: ☐ 未完了
F30: ☐ 未完了
F31: ☐ 未完了
F32: ☐ 未完了
F33: ☐ 未完了
F34: ☐ 未完了
F35: ☐ 未完了
F36: ☐ 未完了
F37: ☐ 未完了
A38: 完了数 | B38: =COUNTIF(F26:F37,"☑ 完了")&" / "&COUNTA(B26:B37)&" 件（記入した行動のうち）"
A40: 30日・60日・90日のふり返り
A41: できたこと・できなかったこと・気づいたことを書きます。できなかったことは「計画を調整するヒント」です。
A42: 節目 | B42: ふり返った日 | C42: できたこと・気づいたこと・次にやること
A43: 30日目
A44: 60日目
A45: 90日目
A47: 90日が終わったら、11_私の働き方の取扱説明書を更新しましょう。01_働き方セルフチェックの「3か月後の回答」もおすすめです。

Sheet 11_私の働き方の取扱説明書
B2: 私の働き方の取扱説明書
B3: HSPの働き方ゼミ｜迷ったとき、何度でも戻ってこられる自分専用の判断ツール
B5: 名前 | E5: 更新
B6: 各カードは、これまでのシートの「★まとめ欄」から自動で反映されます。言い回しを整えたい場合は、このシートに直接書き込んでもOKです（直接書くと自動反映は止まります）。
B8: ■ 私が消耗しやすい条件 TOP5 | E8: ■ 私が働きやすい条件 TOP5
B9: 1 | C9: =IF('02_消耗ポイント'!B42="","",'02_消耗ポイント'!B42) | E9: 1 | F9: =IF('03_働きやすい条件'!B43="","",'03_働きやすい条件'!B43)
B10: 2 | C10: =IF('02_消耗ポイント'!B43="","",'02_消耗ポイント'!B43) | E10: 2 | F10: =IF('03_働きやすい条件'!B44="","",'03_働きやすい条件'!B44)
B11: 3 | C11: =IF('02_消耗ポイント'!B44="","",'02_消耗ポイント'!B44) | E11: 3 | F11: =IF('03_働きやすい条件'!B45="","",'03_働きやすい条件'!B45)
B12: 4 | C12: =IF('02_消耗ポイント'!B45="","",'02_消耗ポイント'!B45) | E12: 4 | F12: =IF('03_働きやすい条件'!B46="","",'03_働きやすい条件'!B46)
B13: 5 | C13: =IF('02_消耗ポイント'!B46="","",'02_消耗ポイント'!B46) | E13: 5 | F13: =IF('03_働きやすい条件'!B47="","",'03_働きやすい条件'!B47)
B15: ■ 私が頑張りすぎる3つのパターン （→ そのときの対処法）
B16: 1 | C16: =IF('04_頑張りすぎパターン'!B25="","",'04_頑張りすぎパターン'!B25&IF('04_頑張りすぎパターン'!F25="",""," → "&'04_頑張りすぎパターン'!F25))
B17: 2 | C17: =IF('04_頑張りすぎパターン'!B26="","",'04_頑張りすぎパターン'!B26&IF('04_頑張りすぎパターン'!F26="",""," → "&'04_頑張りすぎパターン'!F26))
B18: 3 | C18: =IF('04_頑張りすぎパターン'!B27="","",'04_頑張りすぎパターン'!B27&IF('04_頑張りすぎパターン'!F27="",""," → "&'04_頑張りすぎパターン'!F27))
B20: ■ 私を守る5つの働き方ルール
B21: 1 | C21: =IF('06_仕事の境界線'!B24="","",'06_仕事の境界線'!B24)
B22: 2 | C22: =IF('06_仕事の境界線'!B25="","",'06_仕事の境界線'!B25)
B23: 3 | C23: =IF('06_仕事の境界線'!B26="","",'06_仕事の境界線'!B26)
B24: 4 | C24: =IF('06_仕事の境界線'!B27="","",'06_仕事の境界線'!B27)
B25: 5 | C25: =IF('06_仕事の境界線'!B28="","",'06_仕事の境界線'!B28)
B27: ■ 困ったときの相談先
B28: 仕事量・業務のこと | E28: =IF('07_相談ルート'!C22="","",'07_相談ルート'!C22&IF('07_相談ルート'!D22="",""," （"&'07_相談ルート'!D22&"）"))
B29: 職場の人間関係 | E29: =IF('07_相談ルート'!C23="","",'07_相談ルート'!C23&IF('07_相談ルート'!D23="",""," （"&'07_相談ルート'!D23&"）"))
B30: 心と体の不調 | E30: =IF('07_相談ルート'!C24="","",'07_相談ルート'!C24&IF('07_相談ルート'!D24="",""," （"&'07_相談ルート'!D24&"）"))
B31: キャリア・転職のこと | E31: =IF('07_相談ルート'!C25="","",'07_相談ルート'!C25&IF('07_相談ルート'!D25="",""," （"&'07_相談ルート'!D25&"）"))
B33: ■ 今の会社に残れる条件 | E33: ■ 環境を変える・転職を考えるサイン
B34: 1 | C34: =IF('08_残る・転職する判断基準'!B27="","",'08_残る・転職する判断基準'!B27) | E34: 1 | F34: =IF('08_残る・転職する判断基準'!B34="","",'08_残る・転職する判断基準'!B34)
B35: 2 | C35: =IF('08_残る・転職する判断基準'!B28="","",'08_残る・転職する判断基準'!B28) | E35: 2 | F35: =IF('08_残る・転職する判断基準'!B35="","",'08_残る・転職する判断基準'!B35)
B36: 3 | C36: =IF('08_残る・転職する判断基準'!B29="","",'08_残る・転職する判断基準'!B29) | E36: 3 | F36: =IF('08_残る・転職する判断基準'!B36="","",'08_残る・転職する判断基準'!B36)
B37: 現時点の判断 | E37: =IF('08_残る・転職する判断基準'!B39="","",'08_残る・転職する判断基準'!B39)
B39: ■ 次の職場の Must条件 | E39: ■ 次の職場の NG条件
B40: 1 | C40: =IF('09_Must・Want・NG'!B32="","",'09_Must・Want・NG'!B32) | E40: 1 | F40: =IF('09_Must・Want・NG'!B41="","",'09_Must・Want・NG'!B41)
B41: 2 | C41: =IF('09_Must・Want・NG'!B33="","",'09_Must・Want・NG'!B33) | E41: 2 | F41: =IF('09_Must・Want・NG'!B42="","",'09_Must・Want・NG'!B42)
B42: 3 | C42: =IF('09_Must・Want・NG'!B34="","",'09_Must・Want・NG'!B34) | E42: 3 | F42: =IF('09_Must・Want・NG'!B43="","",'09_Must・Want・NG'!B43)
B43: 4 | C43: =IF('09_Must・Want・NG'!B35="","",'09_Must・Want・NG'!B35) | E43: 4 | F43: =IF('09_Must・Want・NG'!B44="","",'09_Must・Want・NG'!B44)
B44: 5 | C44: =IF('09_Must・Want・NG'!B36="","",'09_Must・Want・NG'!B36) | E44: 5 | F44: =IF('09_Must・Want・NG'!B45="","",'09_Must・Want・NG'!B45)
B46: ■ 絶対にやりたくないこと
B47: 1 | C47: =IF('09_Must・Want・NG'!B53="","",'09_Must・Want・NG'!B53) | E47: 6 | F47: =IF('09_Must・Want・NG'!B58="","",'09_Must・Want・NG'!B58)
B48: 2 | C48: =IF('09_Must・Want・NG'!B54="","",'09_Must・Want・NG'!B54) | E48: 7 | F48: =IF('09_Must・Want・NG'!B59="","",'09_Must・Want・NG'!B59)
B49: 3 | C49: =IF('09_Must・Want・NG'!B55="","",'09_Must・Want・NG'!B55) | E49: 8 | F49: =IF('09_Must・Want・NG'!B60="","",'09_Must・Want・NG'!B60)
...
